// Decompiled by Jad v1.5.8g. Copyright 2001 Pavel Kouznetsov.
// Jad home page: http://www.kpdus.com/jad.html
// Decompiler options: packimports(3) braces deadcode fieldsfirst 

package net.minecraft.src;

import java.util.List;
import java.util.Random;

// Referenced classes of package net.minecraft.src:
//            ComponentVillage, StructureBoundingBox, StructureComponent, Block, 
//            World

public class ComponentVillageHouse2 extends ComponentVillage {

	private int field_35086_a;

	public ComponentVillageHouse2(int i, Random random, StructureBoundingBox structureboundingbox, int j) {
		super(i);
		field_35086_a = -1;
		coordBaseMode = j;
		boundingBox = structureboundingbox;
	}

	@Override
	public void buildComponent(StructureComponent structurecomponent, List list, Random random) {
	}

	public static ComponentVillageHouse2 func_35085_a(List list, Random random, int i, int j, int k, int l, int i1) {
		StructureBoundingBox structureboundingbox = StructureBoundingBox.getComponentToAddBoundingBox(i, j, k, 0, 0, 0, 10, 6, 7, l);
		if(!canVillageGoDeeper(structureboundingbox) || StructureComponent.getIntersectingStructureComponent(list, structureboundingbox) != null) {
			return null;
		} else {
			return new ComponentVillageHouse2(i1, random, structureboundingbox, l);
		}
	}

	@Override
	public boolean addComponentParts(World world, Random random, StructureBoundingBox structureboundingbox) {
		if(field_35086_a < 0) {
			field_35086_a = getAverageGroundLevel(world, structureboundingbox);
			if(field_35086_a < 0) {
				return true;
			}
			boundingBox.offset(0, ((field_35086_a - boundingBox.maxY) + 6) - 1, 0);
		}
		fillWithBlocks(world, structureboundingbox, 0, 1, 0, 9, 4, 6, 0, 0, false);
		fillWithBlocks(world, structureboundingbox, 0, 0, 0, 9, 0, 6, Block.cobblestone.blockID, Block.cobblestone.blockID, false);
		fillWithBlocks(world, structureboundingbox, 0, 4, 0, 9, 4, 6, Block.cobblestone.blockID, Block.cobblestone.blockID, false);
		fillWithBlocks(world, structureboundingbox, 0, 5, 0, 9, 5, 6, Block.stairSingle.blockID, Block.stairSingle.blockID, false);
		fillWithBlocks(world, structureboundingbox, 1, 5, 1, 8, 5, 5, 0, 0, false);
		fillWithBlocks(world, structureboundingbox, 1, 1, 0, 2, 3, 0, Block.planks.blockID, Block.planks.blockID, false);
		fillWithBlocks(world, structureboundingbox, 0, 1, 0, 0, 4, 0, Block.wood.blockID, Block.wood.blockID, false);
		fillWithBlocks(world, structureboundingbox, 3, 1, 0, 3, 4, 0, Block.wood.blockID, Block.wood.blockID, false);
		fillWithBlocks(world, structureboundingbox, 0, 1, 6, 0, 4, 6, Block.wood.blockID, Block.wood.blockID, false);
		placeBlockAtCurrentPosition(world, Block.planks.blockID, 0, 3, 3, 1, structureboundingbox);
		fillWithBlocks(world, structureboundingbox, 3, 1, 2, 3, 3, 2, Block.planks.blockID, Block.planks.blockID, false);
		fillWithBlocks(world, structureboundingbox, 4, 1, 3, 5, 3, 3, Block.planks.blockID, Block.planks.blockID, false);
		fillWithBlocks(world, structureboundingbox, 0, 1, 1, 0, 3, 5, Block.planks.blockID, Block.planks.blockID, false);
		fillWithBlocks(world, structureboundingbox, 1, 1, 6, 5, 3, 6, Block.planks.blockID, Block.planks.blockID, false);
		fillWithBlocks(world, structureboundingbox, 5, 1, 0, 5, 3, 0, Block.fence.blockID, Block.fence.blockID, false);
		fillWithBlocks(world, structureboundingbox, 9, 1, 0, 9, 3, 0, Block.fence.blockID, Block.fence.blockID, false);
		fillWithBlocks(world, structureboundingbox, 6, 1, 4, 9, 4, 6, Block.cobblestone.blockID, Block.cobblestone.blockID, false);
		placeBlockAtCurrentPosition(world, Block.lavaMoving.blockID, 0, 7, 1, 5, structureboundingbox);
		placeBlockAtCurrentPosition(world, Block.lavaMoving.blockID, 0, 8, 1, 5, structureboundingbox);
		placeBlockAtCurrentPosition(world, Block.fenceIron.blockID, 0, 9, 2, 5, structureboundingbox);
		placeBlockAtCurrentPosition(world, Block.fenceIron.blockID, 0, 9, 2, 4, structureboundingbox);
		fillWithBlocks(world, structureboundingbox, 7, 2, 4, 8, 2, 5, 0, 0, false);
		placeBlockAtCurrentPosition(world, Block.cobblestone.blockID, 0, 6, 1, 3, structureboundingbox);
		placeBlockAtCurrentPosition(world, Block.stoneOvenIdle.blockID, 0, 6, 2, 3, structureboundingbox);
		placeBlockAtCurrentPosition(world, Block.stoneOvenIdle.blockID, 0, 6, 3, 3, structureboundingbox);
		placeBlockAtCurrentPosition(world, Block.stairDouble.blockID, 0, 8, 1, 1, structureboundingbox);
		placeBlockAtCurrentPosition(world, Block.thinGlass.blockID, 0, 0, 2, 2, structureboundingbox);
		placeBlockAtCurrentPosition(world, Block.thinGlass.blockID, 0, 0, 2, 4, structureboundingbox);
		placeBlockAtCurrentPosition(world, Block.thinGlass.blockID, 0, 2, 2, 6, structureboundingbox);
		placeBlockAtCurrentPosition(world, Block.thinGlass.blockID, 0, 4, 2, 6, structureboundingbox);
		placeBlockAtCurrentPosition(world, Block.fence.blockID, 0, 2, 1, 4, structureboundingbox);
		placeBlockAtCurrentPosition(world, Block.pressurePlatePlanks.blockID, 0, 2, 2, 4, structureboundingbox);
		placeBlockAtCurrentPosition(world, Block.planks.blockID, 0, 1, 1, 5, structureboundingbox);
		placeBlockAtCurrentPosition(world, Block.stairCompactPlanks.blockID, func_35009_c(Block.stairCompactPlanks.blockID, 3), 2, 1, 5, structureboundingbox);
		placeBlockAtCurrentPosition(world, Block.stairCompactPlanks.blockID, func_35009_c(Block.stairCompactPlanks.blockID, 1), 1, 1, 4, structureboundingbox);
		for(int i = 6; i <= 8; i++) {
			if(getBlockIdAtCurrentPosition(world, i, 0, -1, structureboundingbox) == 0 && getBlockIdAtCurrentPosition(world, i, -1, -1, structureboundingbox) != 0) {
				placeBlockAtCurrentPosition(world, Block.stairCompactCobblestone.blockID, func_35009_c(Block.stairCompactCobblestone.blockID, 3), i, 0, -1, structureboundingbox);
			}
		}

		for(int j = 0; j < 7; j++) {
			for(int k = 0; k < 10; k++) {
				clearCurrentPositionBlocksUpwards(world, k, 6, j, structureboundingbox);
				fillCurrentPositionBlocksDownwards(world, Block.cobblestone.blockID, 0, k, -1, j, structureboundingbox);
			}

		}

		func_40044_a(world, structureboundingbox, 7, 1, 1, 1);
		return true;
	}

	@Override
	protected int func_40043_a(int i) {
		return 3;
	}
}
